<robot
  name="phantomx_pincher_robot_arm_edited">
  <link
    name="base_link">
    <inertial>
      <origin
        xyz="-0.061828 0.039179 0.29608"
        rpy="0 0 0" />
      <mass
        value="0.12375" />
      <inertia
        ixx="0.00023912"
        ixy="-4.8869E-05"
        ixz="-3.6962E-08"
        iyy="0.00026087"
        iyz="6.5556E-08"
        izz="0.00027442" />
    </inertial>
    <visual>
      <origin
        xyz="0 0 0"
        rpy="0 0 0" />
      <geometry>
        <mesh
          filename="package://phantomx_pincher_robot_arm_edited/meshes/base_link.STL" />
      </geometry>
      <material
        name="">
        <color
          rgba="0.79216 0.81961 0.93333 1" />
      </material>
    </visual>
    <collision>
      <origin
        xyz="0 0 0"
        rpy="0 0 0" />
      <geometry>
        <mesh
          filename="package://phantomx_pincher_robot_arm_edited/meshes/base_link.STL" />
      </geometry>
    </collision>
  </link>
  <link
    name="arm_shoulder_pan_link">
    <inertial>
      <origin
        xyz="4.6716E-05 0.0010278 0.027716"
        rpy="0 0 0" />
      <mass
        value="0.043526" />
      <inertia
        ixx="1.3502E-05"
        ixy="-1.1957E-10"
        ixz="1.2676E-08"
        iyy="1.1436E-05"
        iyz="-1.3637E-07"
        izz="7.0195E-06" />
    </inertial>
    <visual>
      <origin
        xyz="0 0 0"
        rpy="0 0 0" />
      <geometry>
        <mesh
          filename="package://phantomx_pincher_robot_arm_edited/meshes/arm_shoulder_pan_link.STL" />
      </geometry>
      <material
        name="">
        <color
          rgba="0.79216 0.81961 0.93333 1" />
      </material>
    </visual>
    <collision>
      <origin
        xyz="0 0 0"
        rpy="0 0 0" />
      <geometry>
        <mesh
          filename="package://phantomx_pincher_robot_arm_edited/meshes/arm_shoulder_pan_link.STL" />
      </geometry>
    </collision>
  </link>
  <joint
    name="arm_shoulder_pan_joint"
    type="continuous">
    <origin
      xyz="-0.034767 -0.2961 0.089775"
      rpy="-6.123E-17 0 0" />
    <parent
      link="base_link" />
    <child
      link="arm_shoulder_pan_link" />
    <axis
      xyz="0 0 1" />
  </joint>
  <link
    name="arm_shoulder_lift_link">
    <inertial>
      <origin
        xyz="1.6294E-05 0.0027459 0.080963"
        rpy="0 0 0" />
      <mass
        value="0.059999" />
      <inertia
        ixx="4.6042E-05"
        ixy="-1.4659E-09"
        ixz="-6.036E-09"
        iyy="4.1352E-05"
        iyz="-6.8503E-07"
        izz="1.1532E-05" />
    </inertial>
    <visual>
      <origin
        xyz="0 0 0"
        rpy="0 0 0" />
      <geometry>
        <mesh
          filename="package://phantomx_pincher_robot_arm_edited/meshes/arm_shoulder_lift_link.STL" />
      </geometry>
      <material
        name="">
        <color
          rgba="0.79216 0.81961 0.93333 1" />
      </material>
    </visual>
    <collision>
      <origin
        xyz="0 0 0"
        rpy="0 0 0" />
      <geometry>
        <mesh
          filename="package://phantomx_pincher_robot_arm_edited/meshes/arm_shoulder_lift_link.STL" />
      </geometry>
    </collision>
  </link>
  <joint
    name="arm_shoulder_lift_joint"
    type="continuous">
    <origin
      xyz="0 0 0.0415"
      rpy="0 0 0" />
    <parent
      link="arm_shoulder_pan_link" />
    <child
      link="arm_shoulder_lift_link" />
    <axis
      xyz="0 -1 0" />
  </joint>
  <link
    name="arm_elbow_flex_link">
    <inertial>
      <origin
        xyz="1.6294E-05 0.0047459 0.080963"
        rpy="0 0 0" />
      <mass
        value="0.059999" />
      <inertia
        ixx="4.6042E-05"
        ixy="-1.4659E-09"
        ixz="-6.036E-09"
        iyy="4.1352E-05"
        iyz="-6.8503E-07"
        izz="1.1532E-05" />
    </inertial>
    <visual>
      <origin
        xyz="0 0 0"
        rpy="0 0 0" />
      <geometry>
        <mesh
          filename="package://phantomx_pincher_robot_arm_edited/meshes/arm_elbow_flex_link.STL" />
      </geometry>
      <material
        name="">
        <color
          rgba="0.79216 0.81961 0.93333 1" />
      </material>
    </visual>
    <collision>
      <origin
        xyz="0 0 0"
        rpy="0 0 0" />
      <geometry>
        <mesh
          filename="package://phantomx_pincher_robot_arm_edited/meshes/arm_elbow_flex_link.STL" />
      </geometry>
    </collision>
  </link>
  <joint
    name="arm_elbow_flex_joint"
    type="continuous">
    <origin
      xyz="0 0 0.107"
      rpy="2.7756E-15 0 0" />
    <parent
      link="arm_shoulder_lift_link" />
    <child
      link="arm_elbow_flex_link" />
    <axis
      xyz="0 -1 0" />
  </joint>
  <link
    name="arm_wrist_flex_link">
    <inertial>
      <origin
        xyz="-0.010776 0.006036 0.043911"
        rpy="0 0 0" />
      <mass
        value="0.051345" />
      <inertia
        ixx="1.4469E-05"
        ixy="1.5248E-08"
        ixz="1.8716E-06"
        iyy="1.9641E-05"
        iyz="-1.4162E-09"
        izz="1.4356E-05" />
    </inertial>
    <visual>
      <origin
        xyz="0 0 0"
        rpy="0 0 0" />
      <geometry>
        <mesh
          filename="package://phantomx_pincher_robot_arm_edited/meshes/arm_wrist_flex_link.STL" />
      </geometry>
      <material
        name="">
        <color
          rgba="0.79216 0.81961 0.93333 1" />
      </material>
    </visual>
    <collision>
      <origin
        xyz="0 0 0"
        rpy="0 0 0" />
      <geometry>
        <mesh
          filename="package://phantomx_pincher_robot_arm_edited/meshes/arm_wrist_flex_link.STL" />
      </geometry>
    </collision>
  </link>
  <joint
    name="arm_wrist_flex_joint"
    type="continuous">
    <origin
      xyz="0 0 0.107"
      rpy="-2.7756E-15 0 0" />
    <parent
      link="arm_elbow_flex_link" />
    <child
      link="arm_wrist_flex_link" />
    <axis
      xyz="0 -1 0" />
  </joint>
  <link
    name="arm_wrist_revol_link">
    <inertial>
      <origin
        xyz="-0.0108034643995503 3.0040816245358E-05 0.0211998773417284"
        rpy="0 0 0" />
      <mass
        value="0.0518984073943084" />
      <inertia
        ixx="1.34700180494404E-05"
        ixy="1.72078044521259E-08"
        ixz="-8.87346267942534E-07"
        iyy="1.80627817124038E-05"
        iyz="1.00091470877893E-09"
        izz="1.68525403850811E-05" />
    </inertial>
    <visual>
      <origin
        xyz="0 0 0"
        rpy="0 0 0" />
      <geometry>
        <mesh
          filename="package://phantomx_pincher_robot_arm_edited/meshes/arm_wrist_revol_link.STL" />
      </geometry>
      <material
        name="">
        <color
          rgba="0.792156862745098 0.819607843137255 0.933333333333333 1" />
      </material>
    </visual>
    <collision>
      <origin
        xyz="0 0 0"
        rpy="0 0 0" />
      <geometry>
        <mesh
          filename="package://phantomx_pincher_robot_arm_edited/meshes/arm_wrist_revol_link.STL" />
      </geometry>
    </collision>
  </link>
  <joint
    name="arm_wrist_revol_joint"
    type="continuous">
    <origin
      xyz="-0.00025427 0.006 0.06645"
      rpy="0 -1.1102E-14 3.1416" />
    <parent
      link="arm_wrist_flex_link" />
    <child
      link="arm_wrist_revol_link" />
    <axis
      xyz="0 0 1" />
  </joint>
  <link
    name="left_gripper_link">
    <inertial>
      <origin
        xyz="4.94375373971678E-13 -0.00740598995443981 0.0112693127189871"
        rpy="0 0 0" />
      <mass
        value="0.00650667742243688" />
      <inertia
        ixx="1.06306547840632E-06"
        ixy="-4.08934939007386E-17"
        ixz="1.74854685271235E-17"
        iyy="1.67561330218171E-06"
        iyz="-2.61875963021117E-07"
        izz="1.09598567531698E-06" />
    </inertial>
    <visual>
      <origin
        xyz="0 0 0"
        rpy="0 0 0" />
      <geometry>
        <mesh
          filename="package://phantomx_pincher_robot_arm_edited/meshes/left_gripper_link.STL" />
      </geometry>
      <material
        name="">
        <color
          rgba="0.792156862745098 0.819607843137255 0.933333333333333 1" />
      </material>
    </visual>
    <collision>
      <origin
        xyz="0 0 0"
        rpy="0 0 0" />
      <geometry>
        <mesh
          filename="package://phantomx_pincher_robot_arm_edited/meshes/left_gripper_link.STL" />
      </geometry>
    </collision>
  </link>
  <joint
    name="left_gripper_joint"
    type="prismatic">
    <origin
      xyz="0.00015 -0.015611 0.042144"
      rpy="-5.5511E-15 0 6.163E-29" />
    <parent
      link="arm_wrist_revol_link" />
    <child
      link="left_gripper_link" />
    <axis
      xyz="0 1 0" />
    <limit
      effort="0"
      velocity="0" />
  </joint>
  <link
    name="right_gripper_link">
    <inertial>
      <origin
        xyz="4.94437824016813E-13 -0.00740598995443975 0.011269312718987"
        rpy="0 0 0" />
      <mass
        value="0.00650667742243691" />
      <inertia
        ixx="1.06306547840632E-06"
        ixy="-4.08970086459739E-17"
        ixz="1.74825559213525E-17"
        iyy="1.67561330218171E-06"
        iyz="-2.61875963021119E-07"
        izz="1.09598567531698E-06" />
    </inertial>
    <visual>
      <origin
        xyz="0 0 0"
        rpy="0 0 0" />
      <geometry>
        <mesh
          filename="package://phantomx_pincher_robot_arm_edited/meshes/right_gripper_link.STL" />
      </geometry>
      <material
        name="">
        <color
          rgba="0.792156862745098 0.819607843137255 0.933333333333333 1" />
      </material>
    </visual>
    <collision>
      <origin
        xyz="0 0 0"
        rpy="0 0 0" />
      <geometry>
        <mesh
          filename="package://phantomx_pincher_robot_arm_edited/meshes/right_gripper_link.STL" />
      </geometry>
    </collision>
  </link>
  <joint
    name="right_gripper_joint"
    type="prismatic">
    <origin
      xyz="0.00015 0.015117 0.042144"
      rpy="0 -1.1102E-14 3.1416" />
    <parent
      link="arm_wrist_revol_link" />
    <child
      link="right_gripper_link" />
    <axis
      xyz="0 -1 0" />
    <limit
      effort="0"
      velocity="0" />
  </joint>
</robot>